Workbook

Sheet Сводка
A1: yaSEO — сводка по трём сценариям
A2: Все числа считаются из листа «Параметры». Это модель на допущениях: конверсии, отток и поток посетителей до беты не измерены.
A4: Показатель | B4: Осторожный | C4: Средний | D4: Смелый
A5: Активные подписчики, месяц 12 | B5: =Осторожный!M13 -> 1.5711768 | C5: =Средний!M13 -> 21.670204 | D5: =Смелый!M13 -> 269.23986
A6: Активные подписчики, месяц 24 | B6: =Осторожный!Y13 -> 2.8978111 | C6: =Средний!Y13 -> 46.3817 | D6: =Смелый!Y13 -> 726.27514
A7: Выручка подписок за месяц 12 | B7: =Осторожный!M18 -> 4442.1881 | C7: =Средний!M18 -> 72911.568 | D7: =Смелый!M18 -> 1071843.9
A8: Выручка подписок за месяц 24 | B8: =Осторожный!Y18 -> 8192.9814 | C8: =Средний!Y18 -> 156055.87 | D8: =Смелый!Y18 -> 2891301.3
A9: Выручка за первый год | B9: =SUM(Осторожный!B20:M20) -> 32098.595 | C9: =SUM(Средний!B20:M20) -> 521052.5 | D9: =SUM(Смелый!B20:M20) -> 7149684.2
A10: Выручка за второй год | B10: =SUM(Осторожный!N20:Y20) -> 80077.996 | C10: =SUM(Средний!N20:Y20) -> 1454192 | D10: =SUM(Смелый!N20:Y20) -> 24191992
A11: Прибыль за первый год | B11: =SUM(Осторожный!B38:M38) -> -116002.16 | C11: =SUM(Средний!B38:M38) -> -105871.02 | D11: =SUM(Смелый!B38:M38) -> 4145770.5
A12: Прибыль за второй год | B12: =SUM(Осторожный!N38:Y38) -> -81470.25 | C12: =SUM(Средний!N38:Y38) -> 591811.34 | D12: =SUM(Смелый!N38:Y38) -> 16762762
A13: Накопленный итог на конец месяца 24 | B13: =Осторожный!Y39 -> -197472.41 | C13: =Средний!Y39 -> 485940.32 | D13: =Смелый!Y39 -> 20908532
A14: Самая глубокая яма (сколько денег нужно вложить) | B14: =MIN(0,MIN(Осторожный!B39:Y39)) -> -197472.41 | C14: =MIN(0,MIN(Средний!B39:Y39)) -> -143714.21 | D14: =MIN(0,MIN(Смелый!B39:Y39)) -> -24320.749
A15: Первый прибыльный месяц | B15: =IFERROR(MATCH(1,Осторожный!B40:Y40,0),"за 24 месяца нет") -> за 24 месяца нет | C15: =IFERROR(MATCH(1,Средний!B40:Y40,0),"за 24 месяца нет") -> 9 | D15: =IFERROR(MATCH(1,Смелый!B40:Y40,0),"за 24 месяца нет") -> 2
A16: Месяц возврата вложений | B16: =IFERROR(MATCH(1,Осторожный!B41:Y41,0),"за 24 месяца нет") -> за 24 месяца нет | C16: =IFERROR(MATCH(1,Средний!B41:Y41,0),"за 24 месяца нет") -> 16 | D16: =IFERROR(MATCH(1,Смелый!B41:Y41,0),"за 24 месяца нет") -> 2
A17: Подписчиков для выхода в ноль при текущих расходах | B17: =IF(B19>0,(Параметры!$B$32+Параметры!$B$33+Параметры!$B$34+Параметры!$B$35+Параметры!$B$36+Параметры!$B$41+Параметры!$B$37+Параметры!$B$28/12)/B19,0) -> 5.7589846 | C17: =IF(C19>0,(Параметры!$C$32+Параметры!$C$33+Параметры!$C$34+Параметры!$C$35+Параметры!$C$36+Параметры!$C$41+Параметры!$C$37+Параметры!$C$28/12)/C19,0) -> 16.556182 | D17: =IF(D19>0,(Параметры!$D$32+Параметры!$D$33+Параметры!$D$34+Параметры!$D$35+Параметры!$D$36+Параметры!$D$41+Параметры!$D$37+Параметры!$D$28/12)/D19,0) -> 36.713112
A18: Средний чек подписки | B18: =Параметры!$B$49*Параметры!$B$6+Параметры!$B$50*Параметры!$B$7+Параметры!$B$51*Параметры!$B$8 -> 2827.3 | C18: =Параметры!$C$49*Параметры!$C$6+Параметры!$C$50*Параметры!$C$7+Параметры!$C$51*Параметры!$C$8 -> 3364.6 | D18: =Параметры!$D$49*Параметры!$D$6+Параметры!$D$50*Параметры!$D$7+Параметры!$D$51*Параметры!$D$8 -> 3981
A19: Маржа с подписчика в месяц | B19: =B18*(1-Параметры!$B$24-Параметры!$B$25-Параметры!$B$30)-(Параметры!$B$49*Параметры!$B$11+Параметры!$B$50*Параметры!$B$12+Параметры!$B$51*Параметры!$B$13)*Параметры!$B$16-(Параметры!$B$49*Параметры!$B$20+Параметры!$B$50*Параметры!$B$21+Параметры!$B$51*Параметры!$B$22)*Параметры!$B$16*Параметры!$B$18 -> 2011.0316 | C19: =C18*(1-Параметры!$C$24-Параметры!$C$25-Параметры!$C$30)-(Параметры!$C$49*Параметры!$C$11+Параметры!$C$50*Параметры!$C$12+Параметры!$C$51*Параметры!$C$13)*Параметры!$C$16-(Параметры!$C$49*Параметры!$C$20+Параметры!$C$50*Параметры!$C$21+Параметры!$C$51*Параметры!$C$22)*Параметры!$C$16*Параметры!$C$18 -> 2511.5392 | D19: =D18*(1-Параметры!$D$24-Параметры!$D$25-Параметры!$D$30)-(Параметры!$D$49*Параметры!$D$11+Параметры!$D$50*Параметры!$D$12+Параметры!$D$51*Параметры!$D$13)*Параметры!$D$16-(Параметры!$D$49*Параметры!$D$20+Параметры!$D$50*Параметры!$D$21+Параметры!$D$51*Параметры!$D$22)*Параметры!$D$16*Параметры!$D$18 -> 3039.282
A20: Срок жизни подписчика, месяцев | B20: =IF(Параметры!$B$47>0,1/Параметры!$B$47,0) -> 14.285714 | C20: =IF(Параметры!$C$47>0,1/Параметры!$C$47,0) -> 20 | D20: =IF(Параметры!$D$47>0,1/Параметры!$D$47,0) -> 33.333333
A21: Доход с подписчика за срок жизни (LTV) | B21: =B19*B20 -> 28729.023 | C21: =C19*C20 -> 50230.784 | D21: =D19*D20 -> 101309.4
A22: Цена привлечения подписчика из рекламы (CAC) | B22: =IF(Параметры!$B$41=0,"рекламы нет",IF(Параметры!$B$44*Параметры!$B$45>0,Параметры!$B$42/(Параметры!$B$44*Параметры!$B$45),0)) -> рекламы нет | C22: =IF(Параметры!$C$41=0,"рекламы нет",IF(Параметры!$C$44*Параметры!$C$45>0,Параметры!$C$42/(Параметры!$C$44*Параметры!$C$45),0)) -> 31250 | D22: =IF(Параметры!$D$41=0,"рекламы нет",IF(Параметры!$D$44*Параметры!$D$45>0,Параметры!$D$42/(Параметры!$D$44*Параметры!$D$45),0)) -> 7142.8571

Sheet Параметры
A1: yaSEO — параметры финмодели
A2: Синие числа — вводные, их можно менять. Жёлтая заливка — допущения без замера, их проверяет бета. Чёрные и зелёные ячейки — формулы, их не трогать. Общий параметр меняется в столбце «Средний», остальные два подтянутся.
A4: Параметр | B4: Осторожный | C4: Средний | D4: Смелый | E4: Единица | F4: Источник и пояснение
A5: Цены
A6: Старт, подписка в месяц | B6: =C6 -> 1990 | C6: 1990 | D6: =C6 -> 1990 | E6: ₽ | F6: docs/PLAN.md §4, тарифы версии 2 от 30.09.2026. Назначена по ценам конкурентов, не расчётом
A7: Про, подписка в месяц | B7: =C7 -> 4990 | C7: 4990 | D7: =C7 -> 4990 | E7: ₽ | F7: docs/PLAN.md §4, тарифы версии 2 от 30.09.2026
A8: Агентство, подписка в месяц | B8: =C8 -> 12900 | C8: 12900 | D8: =C8 -> 12900 | E8: ₽ | F8: docs/PLAN.md §4, тарифы версии 2 от 30.09.2026
A9: Разовый аудит | B9: =C9 -> 1990 | C9: 1990 | D9: =C9 -> 1990 | E9: ₽ | F9: docs/PLAN.md §4, тарифы версии 2 от 30.09.2026
A10: Себестоимость API Яндекса
A11: Старт при полной выборке лимитов | B11: =C11 -> 335 | C11: 335 | D11: =C11 -> 335 | E11: ₽ в месяц | F11: Тарифы Yandex Search API, aistudio.yandex.ru/ru/docs/search-api/pricing, замер 29.09.2026, с НДС. 300 запросов ежедневно ночью, 2 аудита, 10 проверок в нейросетях
A12: Про при полной выборке лимитов | B12: =C12 -> 1155 | C12: 1155 | D12: =C12 -> 1155 | E12: ₽ в месяц | F12: Тарифы Yandex Search API, aistudio.yandex.ru/ru/docs/search-api/pricing, замер 29.09.2026, с НДС. 1 000 запросов, 5 аудитов, 50 проверок
A13: Агентство при полной выборке лимитов | B13: =C13 -> 3858 | C13: 3858 | D13: =C13 -> 3858 | E13: ₽ в месяц | F13: Тарифы Yandex Search API, aistudio.yandex.ru/ru/docs/search-api/pricing, замер 29.09.2026, с НДС. 3 000 запросов, 20 аудитов, 200 проверок
A14: Один полный аудит | B14: =C14 -> 27.77 | C14: 27.77 | D14: =C14 -> 27.77 | E14: ₽ | F14: Тарифы Yandex Search API, aistudio.yandex.ru/ru/docs/search-api/pricing, замер 29.09.2026, с НДС. 30 запросов выдачи, 60 Wordstat, 5 по регионам, 5 генеративных
A15: Одна бесплатная экспресс-проверка | B15: =C15 -> 0.4 | C15: 0.4 | D15: =C15 -> 0.4 | E15: ₽ | F15: Тарифы Yandex Search API, aistudio.yandex.ru/ru/docs/search-api/pricing, замер 29.09.2026, с НДС. 5 запросов выдачи, 10 Wordstat
A16: Доля лимитов, которую подписчик выбирает на деле | B16: 0.8 | C16: 0.6 | D16: 0.5 | E16: доля | F16: Допущение. Замеряется на бете по журналу расхода
A17: LLM на тексты рекомендаций
A18: Текст одного полного отчёта | B18: =C18 -> 19.2 | C18: 19.2 | D18: =C18 -> 19.2 | E18: ₽ | F18: YandexGPT Pro 5.1, 0,8 ₽ за 1000 токенов с НДС (aistudio.yandex.ru/ru/docs/ai-studio/pricing, прочитано 30.09.2026). Объём 20 000 входных и 4 000 выходных токенов на отчёт — допущение, модель не выбрана
A19: Текст одной экспресс-проверки | B19: =C19 -> 4.8 | C19: 4.8 | D19: =C19 -> 4.8 | E19: ₽ | F19: Та же модель и цена. Объём 5 000 входных и 1 000 выходных токенов — допущение
A20: Старт: полных аудитов в месяц | B20: =C20 -> 2 | C20: 2 | D20: =C20 -> 2 | E20: шт. | F20: docs/PLAN.md §4, тарифы версии 2 от 30.09.2026
A21: Про: полных аудитов в месяц | B21: =C21 -> 5 | C21: 5 | D21: =C21 -> 5 | E21: шт. | F21: docs/PLAN.md §4, тарифы версии 2 от 30.09.2026
A22: Агентство: полных аудитов в месяц | B22: =C22 -> 20 | C22: 20 | D22: =C22 -> 20 | E22: шт. | F22: docs/PLAN.md §4, тарифы версии 2 от 30.09.2026
A23: Платежи и налоги
A24: Эквайринг | B24: =C24 -> 0.038 | C24: 0.038 | D24: =C24 -> 0.038 | E24: доля выручки | F24: ЮKassa: 2,8% за платёж картой плюс 1% за чек при подключении «Чеков от ЮKassa» (yookassa.ru/fees, прочитано 30.09.2026). Без чеков — 3,5%. Комиссия за СБП на сайте не названа
A25: Налог УСН «доходы» | B25: =C25 -> 0.06 | C25: 0.06 | D25: =C25 -> 0.06 | E25: доля выручки | F25: УСН «доходы», базовая ставка 6% (nalog.gov.ru, закон 425-ФЗ, в силе с 01.01.2026). Режим ИП владельцами не выбран. Уменьшение налога на взносы не учтено
A26: Порог выручки за 12 месяцев, после которого платится НДС | B26: =C26 -> 20000000 | C26: 20000000 | D26: =C26 -> 20000000 | E26: ₽ | F26: nalog.gov.ru/new2026, прочитано 30.09.2026: НДС на УСН возникает при доходе свыше 20 млн ₽ за прошлый год. В модели порог проверяется по выручке за последние 12 месяцев — приближение
A27: НДС после порога | B27: =C27 -> 0.05 | C27: 0.05 | D27: =C27 -> 0.05 | E27: доля выручки | F27: nalog.gov.ru/new2026, прочитано 30.09.2026: 5% без вычетов при доходе от 20 до 272,5 млн ₽
A28: Фиксированные страховые взносы ИП за год | B28: =C28 -> 57390 | C28: 57390 | D28: =C28 -> 57390 | E28: ₽ в год | F28: НЕ ПРОВЕРЕНО ПО ПЕРВОИСТОЧНИКУ: число из поисковой выдачи (справочные сайты), статья 430 НК РФ не прочитана
A29: Годовой доход, сверх которого берётся дополнительный взнос | B29: =C29 -> 300000 | C29: 300000 | D29: =C29 -> 300000 | E29: ₽ в год | F29: НЕ ПРОВЕРЕНО ПО ПЕРВОИСТОЧНИКУ: из поисковой выдачи
A30: Дополнительный взнос с дохода сверх порога | B30: =C30 -> 0.01 | C30: 0.01 | D30: =C30 -> 0.01 | E30: доля | F30: НЕ ПРОВЕРЕНО ПО ПЕРВОИСТОЧНИКУ: из поисковой выдачи. Потолок взноса 321 818 ₽ в модели не учтён
A31: Постоянные расходы в месяц
A32: Сервер | B32: =C32 -> 1800 | C32: 1800 | D32: =C32 -> 1800 | E32: ₽ | F32: Timeweb Cloud, тариф Cloud-80: 4 ядра, 8 ГБ, 80 ГБ NVMe (timeweb.cloud/services/cloud-servers, прочитано 30.09.2026). Selectel и Yandex Cloud — около 5 900 ₽
A33: База данных | B33: =C33 -> 999 | C33: 999 | D33: =C33 -> 999 | E33: ₽ | F33: Timeweb Cloud, управляемая PostgreSQL, минимальная конфигурация с публичным IP (timeweb.cloud/services/postgresql, прочитано 30.09.2026)
A34: Онлайн-касса | B34: =C34 -> 0 | C34: 0 | D34: =C34 -> 0 | E34: ₽ | F34: Касса через «Чеки от ЮKassa» без абонентской платы, её цена сидит в эквайринге (1% за чек)
A35: Домен, почта, рассылки | B35: =C35 -> 1000 | C35: 1000 | D35: =C35 -> 1000 | E35: ₽ | F35: Допущение
A36: Прочее: мониторинг, резервные копии, юрист | B36: =C36 -> 3000 | C36: 3000 | D36: =C36 -> 3000 | E36: ₽ | F36: Допущение
A37: Работа владельцев | B37: =C37 -> 0 | C37: 0 | D37: =C37 -> 0 | E37: ₽ | F37: Решение владельцев. При нуле модель показывает прибыль без оплаты вашего времени
A38: Привлечение
A39: Посетители бесплатных каналов в первый месяц | B39: 300 | C39: 600 | D39: 1200 | E39: чел. | F39: Допущение. Каналы: посты Александра, 32 комментария под постом о yaseo
A40: Рост бесплатного потока в месяц | B40: 0.03 | C40: 0.06 | D40: 0.1 | E40: доля | F40: Допущение
A41: Бюджет на рекламу в месяц | B41: 0 | C41: 30000 | D41: 100000 | E41: ₽ | F41: Решение владельцев
...

Sheet Осторожный
A1: yaSEO — сценарий «осторожный», 24 месяцев, ₽
A3: Месяц | B3: 1 | C3: 2 | D3: 3 | E3: 4 | F3: 5 | G3: 6 | H3: 7 | I3: 8 | J3: 9 | K3: 10 | L3: 11 | M3: 12 | N3: 13 | O3: 14 | P3: 15 | Q3: 16 | R3: 17 | S3: 18 | T3: 19 | U3: 20 | V3: 21 | W3: 22 | X3: 23 | Y3: 24
A4: Поток
A5: Посетители бесплатных каналов | B5: =Параметры!$B$39 -> 300 | C5: =B5*(1+Параметры!$B$40) -> 309 | D5: =C5*(1+Параметры!$B$40) -> 318.27 | E5: =D5*(1+Параметры!$B$40) -> 327.8181 | F5: =E5*(1+Параметры!$B$40) -> 337.65264 | G5: =F5*(1+Параметры!$B$40) -> 347.78222 | H5: =G5*(1+Параметры!$B$40) -> 358.21569 | I5: =H5*(1+Параметры!$B$40) -> 368.96216 | J5: =I5*(1+Параметры!$B$40) -> 380.03102 | ... Y5: =X5*(1+Параметры!$B$40) -> 592.07595
A6: Посетители из рекламы | B6: =IF(Параметры!$B$42>0,Параметры!$B$41/Параметры!$B$42,0) -> 0 | C6: =IF(Параметры!$B$42>0,Параметры!$B$41/Параметры!$B$42,0) -> 0 | D6: =IF(Параметры!$B$42>0,Параметры!$B$41/Параметры!$B$42,0) -> 0 | E6: =IF(Параметры!$B$42>0,Параметры!$B$41/Параметры!$B$42,0) -> 0 | F6: =IF(Параметры!$B$42>0,Параметры!$B$41/Параметры!$B$42,0) -> 0 | G6: =IF(Параметры!$B$42>0,Параметры!$B$41/Параметры!$B$42,0) -> 0 | H6: =IF(Параметры!$B$42>0,Параметры!$B$41/Параметры!$B$42,0) -> 0 | I6: =IF(Параметры!$B$42>0,Параметры!$B$41/Параметры!$B$42,0) -> 0 | ... Y6: =IF(Параметры!$B$42>0,Параметры!$B$41/Параметры!$B$42,0) -> 0
A7: Посетители всего | B7: =B5+B6 -> 300 | C7: =C5+C6 -> 309 | D7: =D5+D6 -> 318.27 | E7: =E5+E6 -> 327.8181 | F7: =F5+F6 -> 337.65264 | G7: =G5+G6 -> 347.78222 | H7: =H5+H6 -> 358.21569 | I7: =I5+I6 -> 368.96216 | ... Y7: =Y5+Y6 -> 592.07595
A8: Бесплатные проверки (регистрации) | B8: =B7*Параметры!$B$44 -> 6 | C8: =C7*Параметры!$B$44 -> 6.18 | D8: =D7*Параметры!$B$44 -> 6.3654 | E8: =E7*Параметры!$B$44 -> 6.556362 | F8: =F7*Параметры!$B$44 -> 6.7530529 | G8: =G7*Параметры!$B$44 -> 6.9556444 | H8: =H7*Параметры!$B$44 -> 7.1643138 | I8: =I7*Параметры!$B$44 -> 7.3792432 | ... Y8: =Y7*Параметры!$B$44 -> 11.841519
A9: Новые подписчики | B9: =B8*Параметры!$B$45 -> 0.156 | C9: =C8*Параметры!$B$45 -> 0.16068 | D9: =D8*Параметры!$B$45 -> 0.1655004 | E9: =E8*Параметры!$B$45 -> 0.17046541 | F9: =F8*Параметры!$B$45 -> 0.17557937 | G9: =G8*Параметры!$B$45 -> 0.18084676 | H9: =H8*Параметры!$B$45 -> 0.18627216 | I9: =I8*Параметры!$B$45 -> 0.19186032 | ... Y9: =Y8*Параметры!$B$45 -> 0.3078795
A10: Разовые аудиты | B10: =B8*Параметры!$B$46 -> 0.06 | C10: =C8*Параметры!$B$46 -> 0.0618 | D10: =D8*Параметры!$B$46 -> 0.063654 | E10: =E8*Параметры!$B$46 -> 0.06556362 | F10: =F8*Параметры!$B$46 -> 0.067530529 | G10: =G8*Параметры!$B$46 -> 0.069556444 | H10: =H8*Параметры!$B$46 -> 0.071643138 | I10: =I8*Параметры!$B$46 -> 0.073792432 | ... Y10: =Y8*Параметры!$B$46 -> 0.11841519
A11: Подписчики
A12: Ушло подписчиков | B12: =0 -> 0 | C12: =B13*Параметры!$B$47 -> 0.01092 | D12: =C13*Параметры!$B$47 -> 0.0214032 | E12: =D13*Параметры!$B$47 -> 0.031490004 | F12: =E13*Параметры!$B$47 -> 0.041218283 | G12: =F13*Параметры!$B$47 -> 0.050623559 | H12: =G13*Параметры!$B$47 -> 0.059739183 | I12: =H13*Параметры!$B$47 -> 0.068596491 | J12: =I13*Параметры!$B$47 -> 0.077224959 | ... Y12: =X13*Параметры!$B$47 -> 0.19494109
A13: Активные подписчики | B13: =B9 -> 0.156 | C13: =B13+C9-C12 -> 0.30576 | D13: =C13+D9-D12 -> 0.4498572 | E13: =D13+E9-E12 -> 0.58883261 | F13: =E13+F9-F12 -> 0.7231937 | G13: =F13+G9-G12 -> 0.8534169 | H13: =G13+H9-H12 -> 0.97994987 | I13: =H13+I9-I12 -> 1.1032137 | J13: =I13+J9-J12 -> 1.2236049 | ... Y13: =X13+Y9-Y12 -> 2.8978111
A14: из них Старт | B14: =B13*Параметры!$B$49 -> 0.1248 | C14: =C13*Параметры!$B$49 -> 0.244608 | D14: =D13*Параметры!$B$49 -> 0.35988576 | E14: =E13*Параметры!$B$49 -> 0.47106609 | F14: =F13*Параметры!$B$49 -> 0.57855496 | G14: =G13*Параметры!$B$49 -> 0.68273352 | H14: =H13*Параметры!$B$49 -> 0.7839599 | I14: =I13*Параметры!$B$49 -> 0.88257096 | ... Y14: =Y13*Параметры!$B$49 -> 2.3182489
A15: из них Про | B15: =B13*Параметры!$B$50 -> 0.02652 | C15: =C13*Параметры!$B$50 -> 0.0519792 | D15: =D13*Параметры!$B$50 -> 0.076475724 | E15: =E13*Параметры!$B$50 -> 0.10010154 | F15: =F13*Параметры!$B$50 -> 0.12294293 | G15: =G13*Параметры!$B$50 -> 0.14508087 | H15: =H13*Параметры!$B$50 -> 0.16659148 | I15: =I13*Параметры!$B$50 -> 0.18754633 | ... Y15: =Y13*Параметры!$B$50 -> 0.49262789
A16: из них Агентство | B16: =B13*Параметры!$B$51 -> 0.00468 | C16: =C13*Параметры!$B$51 -> 0.0091728 | D16: =D13*Параметры!$B$51 -> 0.013495716 | E16: =E13*Параметры!$B$51 -> 0.017664978 | F16: =F13*Параметры!$B$51 -> 0.021695811 | G16: =G13*Параметры!$B$51 -> 0.025602507 | H16: =H13*Параметры!$B$51 -> 0.029398496 | I16: =I13*Параметры!$B$51 -> 0.033096411 | ... Y16: =Y13*Параметры!$B$51 -> 0.086934334
A17: Выручка
A18: Подписки | B18: =B14*Параметры!$B$6+B15*Параметры!$B$7+B16*Параметры!$B$8 -> 441.0588 | C18: =C14*Параметры!$B$6+C15*Параметры!$B$7+C16*Параметры!$B$8 -> 864.47525 | D18: =D14*Параметры!$B$6+D15*Параметры!$B$7+D16*Параметры!$B$8 -> 1271.8813 | E18: =E14*Параметры!$B$6+E15*Параметры!$B$7+E16*Параметры!$B$8 -> 1664.8064 | F18: =F14*Параметры!$B$6+F15*Параметры!$B$7+F16*Параметры!$B$8 -> 2044.6855 | G18: =G14*Параметры!$B$6+G15*Параметры!$B$7+G16*Параметры!$B$8 -> 2412.8656 | H18: =H14*Параметры!$B$6+H15*Параметры!$B$7+H16*Параметры!$B$8 -> 2770.6123 | I18: =I14*Параметры!$B$6+I15*Параметры!$B$7+I16*Параметры!$B$8 -> 3119.1161 | ... Y18: =Y14*Параметры!$B$6+Y15*Параметры!$B$7+Y16*Параметры!$B$8 -> 8192.9814
A19: Разовые аудиты | B19: =B10*Параметры!$B$9 -> 119.4 | C19: =C10*Параметры!$B$9 -> 122.982 | D19: =D10*Параметры!$B$9 -> 126.67146 | E19: =E10*Параметры!$B$9 -> 130.4716 | F19: =F10*Параметры!$B$9 -> 134.38575 | G19: =G10*Параметры!$B$9 -> 138.41732 | H19: =H10*Параметры!$B$9 -> 142.56984 | I19: =I10*Параметры!$B$9 -> 146.84694 | ... Y19: =Y10*Параметры!$B$9 -> 235.64623
A20: Выручка всего | B20: =B18+B19 -> 560.4588 | C20: =C18+C19 -> 987.45725 | D20: =D18+D19 -> 1398.5527 | E20: =E18+E19 -> 1795.278 | F20: =F18+F19 -> 2179.0713 | G20: =G18+G19 -> 2551.2829 | H20: =H18+H19 -> 2913.1821 | I20: =I18+I19 -> 3265.963 | ... Y20: =Y18+Y19 -> 8428.6277
A21: Переменные расходы
A22: API Яндекса: подписчики | B22: =(B14*Параметры!$B$11+B15*Параметры!$B$12+B16*Параметры!$B$13)*Параметры!$B$16 -> 72.395232 | C22: =(C14*Параметры!$B$11+C15*Параметры!$B$12+C16*Параметры!$B$13)*Параметры!$B$16 -> 141.89465 | D22: =(D14*Параметры!$B$11+D15*Параметры!$B$12+D16*Параметры!$B$13)*Параметры!$B$16 -> 208.76613 | E22: =(E14*Параметры!$B$11+E15*Параметры!$B$12+E16*Параметры!$B$13)*Параметры!$B$16 -> 273.26073 | F22: =(F14*Параметры!$B$11+F15*Параметры!$B$12+F16*Параметры!$B$13)*Параметры!$B$16 -> 335.61395 | G22: =(G14*Параметры!$B$11+G15*Параметры!$B$12+G16*Параметры!$B$13)*Параметры!$B$16 -> 396.04689 | H22: =(H14*Параметры!$B$11+H15*Параметры!$B$12+H16*Параметры!$B$13)*Параметры!$B$16 -> 454.7673 | I22: =(I14*Параметры!$B$11+I15*Параметры!$B$12+I16*Параметры!$B$13)*Параметры!$B$16 -> 511.97059 | ... Y22: =(Y14*Параметры!$B$11+Y15*Параметры!$B$12+Y16*Параметры!$B$13)*Параметры!$B$16 -> 1344.793
A23: API Яндекса: разовые аудиты | B23: =B10*Параметры!$B$14 -> 1.6662 | C23: =C10*Параметры!$B$14 -> 1.716186 | D23: =D10*Параметры!$B$14 -> 1.7676716 | E23: =E10*Параметры!$B$14 -> 1.8207017 | F23: =F10*Параметры!$B$14 -> 1.8753228 | G23: =G10*Параметры!$B$14 -> 1.9315825 | H23: =H10*Параметры!$B$14 -> 1.9895299 | I23: =I10*Параметры!$B$14 -> 2.0492158 | ... Y23: =Y10*Параметры!$B$14 -> 3.2883898
A24: API Яндекса: бесплатные проверки | B24: =B8*Параметры!$B$15 -> 2.4 | C24: =C8*Параметры!$B$15 -> 2.472 | D24: =D8*Параметры!$B$15 -> 2.54616 | E24: =E8*Параметры!$B$15 -> 2.6225448 | F24: =F8*Параметры!$B$15 -> 2.7012211 | G24: =G8*Параметры!$B$15 -> 2.7822578 | H24: =H8*Параметры!$B$15 -> 2.8657255 | I24: =I8*Параметры!$B$15 -> 2.9516973 | ... Y24: =Y8*Параметры!$B$15 -> 4.7366076
A25: LLM: тексты рекомендаций | B25: =(B14*Параметры!$B$20+B15*Параметры!$B$21+B16*Параметры!$B$22)*Параметры!$B$16*Параметры!$B$18+B10*Параметры!$B$18+B8*Параметры!$B$19 -> 37.260288 | C25: =(C14*Параметры!$B$20+C15*Параметры!$B$21+C16*Параметры!$B$22)*Параметры!$B$16*Параметры!$B$18+C10*Параметры!$B$18+C8*Параметры!$B$19 -> 45.174804 | D25: =(D14*Параметры!$B$20+D15*Параметры!$B$21+D16*Параметры!$B$22)*Параметры!$B$16*Параметры!$B$18+D10*Параметры!$B$18+D8*Параметры!$B$19 -> 52.850987 | E25: =(E14*Параметры!$B$20+E15*Параметры!$B$21+E16*Параметры!$B$22)*Параметры!$B$16*Параметры!$B$18+E10*Параметры!$B$18+E8*Параметры!$B$19 -> 60.314989 | F25: =(F14*Параметры!$B$20+F15*Параметры!$B$21+F16*Параметры!$B$22)*Параметры!$B$16*Параметры!$B$18+F10*Параметры!$B$18+F8*Параметры!$B$19 -> 67.591418 | G25: =(G14*Параметры!$B$20+G15*Параметры!$B$21+G16*Параметры!$B$22)*Параметры!$B$16*Параметры!$B$18+G10*Параметры!$B$18+G8*Параметры!$B$19 -> 74.703452 | H25: =(H14*Параметры!$B$20+H15*Параметры!$B$21+H16*Параметры!$B$22)*Параметры!$B$16*Параметры!$B$18+H10*Параметры!$B$18+H8*Параметры!$B$19 -> 81.672946 | I25: =(I14*Параметры!$B$20+I15*Параметры!$B$21+I16*Параметры!$B$22)*Параметры!$B$16*Параметры!$B$18+I10*Параметры!$B$18+I8*Параметры!$B$19 -> 88.520538 | ... Y25: =(Y14*Параметры!$B$20+Y15*Параметры!$B$21+Y16*Параметры!$B$22)*Параметры!$B$16*Параметры!$B$18+Y10*Параметры!$B$18+Y8*Параметры!$B$19 -> 194.86952
A26: Эквайринг | B26: =B20*Параметры!$B$24 -> 21.297434 | C26: =C20*Параметры!$B$24 -> 37.523375 | D26: =D20*Параметры!$B$24 -> 53.145003 | E26: =E20*Параметры!$B$24 -> 68.220565 | F26: =F20*Параметры!$B$24 -> 82.804709 | G26: =G20*Параметры!$B$24 -> 96.948751 | H26: =H20*Параметры!$B$24 -> 110.70092 | I26: =I20*Параметры!$B$24 -> 124.1066 | ... Y26: =Y20*Параметры!$B$24 -> 320.28785
A27: Налоги и взносы
A28: Выручка за 12 месяцев (для порога НДС) | B28: =SUM(B20) -> 560.4588 | C28: =SUM(B20:C20) -> 1547.916 | D28: =SUM(B20:D20) -> 2946.4688 | E28: =SUM(B20:E20) -> 4741.7468 | F28: =SUM(B20:F20) -> 6920.8181 | G28: =SUM(B20:G20) -> 9472.101 | H28: =SUM(B20:H20) -> 12385.283 | I28: =SUM(B20:I20) -> 15651.246 | J28: =SUM(B20:J20) -> 19261.997 | K28: =SUM(B20:K20) -> 23210.601 | L28: =SUM(B20:L20) -> 27491.129 | M28: =SUM(B20:M20) -> 32098.595 | N28: =SUM(C20:N20) -> 36468.451 | O28: =SUM(D20:O20) -> 40730.92 | P28: =SUM(E20:P20) -> 44899.474 | Q28: =SUM(F20:Q20) -> 48986.821 | R28: =SUM(G20:R20) -> 53004.963 | S28: =SUM(H20:S20) -> 56965.251 | T28: =SUM(I20:T20) -> 60878.439 | ... Y28: =SUM(N20:Y20) -> 80077.996
A29: Налог УСН | B29: =B20*Параметры!$B$25 -> 33.627528 | C29: =C20*Параметры!$B$25 -> 59.247435 | D29: =D20*Параметры!$B$25 -> 83.913163 | E29: =E20*Параметры!$B$25 -> 107.71668 | F29: =F20*Параметры!$B$25 -> 130.74428 | G29: =G20*Параметры!$B$25 -> 153.07697 | H29: =H20*Параметры!$B$25 -> 174.79093 | I29: =I20*Параметры!$B$25 -> 195.95778 | ... Y29: =Y20*Параметры!$B$25 -> 505.71766
A30: НДС | B30: =IF(B28>Параметры!$B$26,B20*Параметры!$B$27,0) -> 0 | C30: =IF(C28>Параметры!$B$26,C20*Параметры!$B$27,0) -> 0 | D30: =IF(D28>Параметры!$B$26,D20*Параметры!$B$27,0) -> 0 | E30: =IF(E28>Параметры!$B$26,E20*Параметры!$B$27,0) -> 0 | F30: =IF(F28>Параметры!$B$26,F20*Параметры!$B$27,0) -> 0 | G30: =IF(G28>Параметры!$B$26,G20*Параметры!$B$27,0) -> 0 | H30: =IF(H28>Параметры!$B$26,H20*Параметры!$B$27,0) -> 0 | I30: =IF(I28>Параметры!$B$26,I20*Параметры!$B$27,0) -> 0 | ... Y30: =IF(Y28>Параметры!$B$26,Y20*Параметры!$B$27,0) -> 0
A31: Страховые взносы ИП | B31: =Параметры!$B$28/12+MAX(0,B20-Параметры!$B$29/12)*Параметры!$B$30 -> 4782.5 | C31: =Параметры!$B$28/12+MAX(0,C20-Параметры!$B$29/12)*Параметры!$B$30 -> 4782.5 | D31: =Параметры!$B$28/12+MAX(0,D20-Параметры!$B$29/12)*Параметры!$B$30 -> 4782.5 | E31: =Параметры!$B$28/12+MAX(0,E20-Параметры!$B$29/12)*Параметры!$B$30 -> 4782.5 | F31: =Параметры!$B$28/12+MAX(0,F20-Параметры!$B$29/12)*Параметры!$B$30 -> 4782.5 | G31: =Параметры!$B$28/12+MAX(0,G20-Параметры!$B$29/12)*Параметры!$B$30 -> 4782.5 | H31: =Параметры!$B$28/12+MAX(0,H20-Параметры!$B$29/12)*Параметры!$B$30 -> 4782.5 | I31: =Параметры!$B$28/12+MAX(0,I20-Параметры!$B$29/12)*Параметры!$B$30 -> 4782.5 | ... Y31: =Параметры!$B$28/12+MAX(0,Y20-Параметры!$B$29/12)*Параметры!$B$30 -> 4782.5
A32: Постоянные расходы
A33: Сервер, база, касса, домен, прочее | B33: =Параметры!$B$32+Параметры!$B$33+Параметры!$B$34+Параметры!$B$35+Параметры!$B$36 -> 6799 | C33: =Параметры!$B$32+Параметры!$B$33+Параметры!$B$34+Параметры!$B$35+Параметры!$B$36 -> 6799 | D33: =Параметры!$B$32+Параметры!$B$33+Параметры!$B$34+Параметры!$B$35+Параметры!$B$36 -> 6799 | E33: =Параметры!$B$32+Параметры!$B$33+Параметры!$B$34+Параметры!$B$35+Параметры!$B$36 -> 6799 | F33: =Параметры!$B$32+Параметры!$B$33+Параметры!$B$34+Параметры!$B$35+Параметры!$B$36 -> 6799 | G33: =Параметры!$B$32+Параметры!$B$33+Параметры!$B$34+Параметры!$B$35+Параметры!$B$36 -> 6799 | H33: =Параметры!$B$32+Параметры!$B$33+Параметры!$B$34+Параметры!$B$35+Параметры!$B$36 -> 6799 | I33: =Параметры!$B$32+Параметры!$B$33+Параметры!$B$34+Параметры!$B$35+Параметры!$B$36 -> 6799 | ... Y33: =Параметры!$B$32+Параметры!$B$33+Параметры!$B$34+Параметры!$B$35+Параметры!$B$36 -> 6799
A34: Реклама | B34: =Параметры!$B$41 -> 0 | C34: =Параметры!$B$41 -> 0 | D34: =Параметры!$B$41 -> 0 | E34: =Параметры!$B$41 -> 0 | F34: =Параметры!$B$41 -> 0 | G34: =Параметры!$B$41 -> 0 | H34: =Параметры!$B$41 -> 0 | I34: =Параметры!$B$41 -> 0 | ... Y34: =Параметры!$B$41 -> 0
A35: Работа владельцев | B35: =Параметры!$B$37 -> 0 | C35: =Параметры!$B$37 -> 0 | D35: =Параметры!$B$37 -> 0 | E35: =Параметры!$B$37 -> 0 | F35: =Параметры!$B$37 -> 0 | G35: =Параметры!$B$37 -> 0 | H35: =Параметры!$B$37 -> 0 | I35: =Параметры!$B$37 -> 0 | ... Y35: =Параметры!$B$37 -> 0
A36: Итог
A37: Расходы всего | B37: =B22+B23+B24+B25+B26+B29+B30+B31+B33+B34+B35 -> 11750.147 | C37: =C22+C23+C24+C25+C26+C29+C30+C31+C33+C34+C35 -> 11869.528 | D37: =D22+D23+D24+D25+D26+D29+D30+D31+D33+D34+D35 -> 11984.489 | E37: =E22+E23+E24+E25+E26+E29+E30+E31+E33+E34+E35 -> 12095.456 | F37: =F22+F23+F24+F25+F26+F29+F30+F31+F33+F34+F35 -> 12202.831 | G37: =G22+G23+G24+G25+G26+G29+G30+G31+G33+G34+G35 -> 12306.99 | H37: =H22+H23+H24+H25+H26+H29+H30+H31+H33+H34+H35 -> 12408.287 | I37: =I22+I23+I24+I25+I26+I29+I30+I31+I33+I34+I35 -> 12507.056 | ... Y37: =Y22+Y23+Y24+Y25+Y26+Y29+Y30+Y31+Y33+Y34+Y35 -> 13955.193
A38: Прибыль за месяц | B38: =B20-B37 -> -11189.688 | C38: =C20-C37 -> -10882.071 | D38: =D20-D37 -> -10585.936 | E38: =E20-E37 -> -10300.178 | F38: =F20-F37 -> -10023.76 | G38: =G20-G37 -> -9755.707 | H38: =H20-H37 -> -9495.1052 | I38: =I20-I37 -> -9241.0934 | ... Y38: =Y20-Y37 -> -5526.5654
A39: Накопленный итог | B39: =B38 -> -11189.688 | C39: =B39+C38 -> -22071.759 | D39: =C39+D38 -> -32657.695 | E39: =D39+E38 -> -42957.874 | F39: =E39+F38 -> -52981.633 | G39: =F39+G38 -> -62737.34 | H39: =G39+H38 -> -72232.445 | I39: =H39+I38 -> -81473.539 | J39: =I39+J38 -> -90466.399 | ... Y39: =X39+Y38 -> -197472.41
A40: Месяц прибыльный (1 — да) | B40: =IF(B38>=0,1,0) -> 0 | C40: =IF(C38>=0,1,0) -> 0 | D40: =IF(D38>=0,1,0) -> 0 | E40: =IF(E38>=0,1,0) -> 0 | F40: =IF(F38>=0,1,0) -> 0 | G40: =IF(G38>=0,1,0) -> 0 | H40: =IF(H38>=0,1,0) -> 0 | I40: =IF(I38>=0,1,0) -> 0 | ... Y40: =IF(Y38>=0,1,0) -> 0
A41: Вложения возвращены (1 — да) | B41: =IF(B39>=0,1,0) -> 0 | C41: =IF(C39>=0,1,0) -> 0 | D41: =IF(D39>=0,1,0) -> 0 | E41: =IF(E39>=0,1,0) -> 0 | F41: =IF(F39>=0,1,0) -> 0 | G41: =IF(G39>=0,1,0) -> 0 | H41: =IF(H39>=0,1,0) -> 0 | I41: =IF(I39>=0,1,0) -> 0 | ... Y41: =IF(Y39>=0,1,0) -> 0

Sheet Средний
A1: yaSEO — сценарий «средний», 24 месяцев, ₽
A3: Месяц | B3: 1 | C3: 2 | D3: 3 | E3: 4 | F3: 5 | G3: 6 | H3: 7 | I3: 8 | J3: 9 | K3: 10 | L3: 11 | M3: 12 | N3: 13 | O3: 14 | P3: 15 | Q3: 16 | R3: 17 | S3: 18 | T3: 19 | U3: 20 | V3: 21 | W3: 22 | X3: 23 | Y3: 24
A4: Поток
A5: Посетители бесплатных каналов | B5: =Параметры!$C$39 -> 600 | C5: =B5*(1+Параметры!$C$40) -> 636 | D5: =C5*(1+Параметры!$C$40) -> 674.16 | E5: =D5*(1+Параметры!$C$40) -> 714.6096 | F5: =E5*(1+Параметры!$C$40) -> 757.48618 | G5: =F5*(1+Параметры!$C$40) -> 802.93535 | H5: =G5*(1+Параметры!$C$40) -> 851.11147 | I5: =H5*(1+Параметры!$C$40) -> 902.17816 | J5: =I5*(1+Параметры!$C$40) -> 956.30884 | ... Y5: =X5*(1+Параметры!$C$40) -> 2291.8498
A6: Посетители из рекламы | B6: =IF(Параметры!$C$42>0,Параметры!$C$41/Параметры!$C$42,0) -> 600 | C6: =IF(Параметры!$C$42>0,Параметры!$C$41/Параметры!$C$42,0) -> 600 | D6: =IF(Параметры!$C$42>0,Параметры!$C$41/Параметры!$C$42,0) -> 600 | E6: =IF(Параметры!$C$42>0,Параметры!$C$41/Параметры!$C$42,0) -> 600 | F6: =IF(Параметры!$C$42>0,Параметры!$C$41/Параметры!$C$42,0) -> 600 | G6: =IF(Параметры!$C$42>0,Параметры!$C$41/Параметры!$C$42,0) -> 600 | H6: =IF(Параметры!$C$42>0,Параметры!$C$41/Параметры!$C$42,0) -> 600 | I6: =IF(Параметры!$C$42>0,Параметры!$C$41/Параметры!$C$42,0) -> 600 | ... Y6: =IF(Параметры!$C$42>0,Параметры!$C$41/Параметры!$C$42,0) -> 600
A7: Посетители всего | B7: =B5+B6 -> 1200 | C7: =C5+C6 -> 1236 | D7: =D5+D6 -> 1274.16 | E7: =E5+E6 -> 1314.6096 | F7: =F5+F6 -> 1357.4862 | G7: =G5+G6 -> 1402.9353 | H7: =H5+H6 -> 1451.1115 | I7: =I5+I6 -> 1502.1782 | ... Y7: =Y5+Y6 -> 2891.8498
A8: Бесплатные проверки (регистрации) | B8: =B7*Параметры!$C$44 -> 48 | C8: =C7*Параметры!$C$44 -> 49.44 | D8: =D7*Параметры!$C$44 -> 50.9664 | E8: =E7*Параметры!$C$44 -> 52.584384 | F8: =F7*Параметры!$C$44 -> 54.299447 | G8: =G7*Параметры!$C$44 -> 56.117414 | H8: =H7*Параметры!$C$44 -> 58.044459 | I8: =I7*Параметры!$C$44 -> 60.087126 | ... Y8: =Y7*Параметры!$C$44 -> 115.67399
A9: Новые подписчики | B9: =B8*Параметры!$C$45 -> 1.92 | C9: =C8*Параметры!$C$45 -> 1.9776 | D9: =D8*Параметры!$C$45 -> 2.038656 | E9: =E8*Параметры!$C$45 -> 2.1033754 | F9: =F8*Параметры!$C$45 -> 2.1719779 | G9: =G8*Параметры!$C$45 -> 2.2446966 | H9: =H8*Параметры!$C$45 -> 2.3217783 | I9: =I8*Параметры!$C$45 -> 2.403485 | ... Y9: =Y8*Параметры!$C$45 -> 4.6269597
A10: Разовые аудиты | B10: =B8*Параметры!$C$46 -> 1.44 | C10: =C8*Параметры!$C$46 -> 1.4832 | D10: =D8*Параметры!$C$46 -> 1.528992 | E10: =E8*Параметры!$C$46 -> 1.5775315 | F10: =F8*Параметры!$C$46 -> 1.6289834 | G10: =G8*Параметры!$C$46 -> 1.6835224 | H10: =H8*Параметры!$C$46 -> 1.7413338 | I10: =I8*Параметры!$C$46 -> 1.8026138 | ... Y10: =Y8*Параметры!$C$46 -> 3.4702198
A11: Подписчики
A12: Ушло подписчиков | B12: =0 -> 0 | C12: =B13*Параметры!$C$47 -> 0.096 | D12: =C13*Параметры!$C$47 -> 0.19008 | E12: =D13*Параметры!$C$47 -> 0.2825088 | F12: =E13*Параметры!$C$47 -> 0.37355213 | G12: =F13*Параметры!$C$47 -> 0.46347342 | H12: =G13*Параметры!$C$47 -> 0.55253457 | I12: =H13*Параметры!$C$47 -> 0.64099676 | J12: =I13*Параметры!$C$47 -> 0.72912118 | ... Y12: =X13*Параметры!$C$47 -> 2.1976179
A13: Активные подписчики | B13: =B9 -> 1.92 | C13: =B13+C9-C12 -> 3.8016 | D13: =C13+D9-D12 -> 5.650176 | E13: =D13+E9-E12 -> 7.4710426 | F13: =E13+F9-F12 -> 9.2694683 | G13: =F13+G9-G12 -> 11.050691 | H13: =G13+H9-H12 -> 12.819935 | I13: =H13+I9-I12 -> 14.582424 | J13: =I13+J9-J12 -> 16.343396 | ... Y13: =X13+Y9-Y12 -> 46.3817
A14: из них Старт | B14: =B13*Параметры!$C$49 -> 1.344 | C14: =C13*Параметры!$C$49 -> 2.66112 | D14: =D13*Параметры!$C$49 -> 3.9551232 | E14: =E13*Параметры!$C$49 -> 5.2297298 | F14: =F13*Параметры!$C$49 -> 6.4886278 | G14: =G13*Параметры!$C$49 -> 7.735484 | H14: =H13*Параметры!$C$49 -> 8.9739547 | I14: =I13*Параметры!$C$49 -> 10.207696 | ... Y14: =Y13*Параметры!$C$49 -> 32.46719
A15: из них Про | B15: =B13*Параметры!$C$50 -> 0.4608 | C15: =C13*Параметры!$C$50 -> 0.912384 | D15: =D13*Параметры!$C$50 -> 1.3560422 | E15: =E13*Параметры!$C$50 -> 1.7930502 | F15: =F13*Параметры!$C$50 -> 2.2246724 | G15: =G13*Параметры!$C$50 -> 2.6521659 | H15: =H13*Параметры!$C$50 -> 3.0767845 | I15: =I13*Параметры!$C$50 -> 3.4997816 | ... Y15: =Y13*Параметры!$C$50 -> 11.131608
A16: из них Агентство | B16: =B13*Параметры!$C$51 -> 0.1152 | C16: =C13*Параметры!$C$51 -> 0.228096 | D16: =D13*Параметры!$C$51 -> 0.33901056 | E16: =E13*Параметры!$C$51 -> 0.44826255 | F16: =F13*Параметры!$C$51 -> 0.5561681 | G16: =G13*Параметры!$C$51 -> 0.66304149 | H16: =H13*Параметры!$C$51 -> 0.76919611 | I16: =I13*Параметры!$C$51 -> 0.87494541 | ... Y16: =Y13*Параметры!$C$51 -> 2.782902
A17: Выручка
A18: Подписки | B18: =B14*Параметры!$C$6+B15*Параметры!$C$7+B16*Параметры!$C$8 -> 6460.032 | C18: =C14*Параметры!$C$6+C15*Параметры!$C$7+C16*Параметры!$C$8 -> 12790.863 | D18: =D14*Параметры!$C$6+D15*Параметры!$C$7+D16*Параметры!$C$8 -> 19010.582 | E18: =E14*Параметры!$C$6+E15*Параметры!$C$7+E16*Параметры!$C$8 -> 25137.07 | F18: =F14*Параметры!$C$6+F15*Параметры!$C$7+F16*Параметры!$C$8 -> 31188.053 | G18: =G14*Параметры!$C$6+G15*Параметры!$C$7+G16*Параметры!$C$8 -> 37181.156 | H18: =H14*Параметры!$C$6+H15*Параметры!$C$7+H16*Параметры!$C$8 -> 43133.954 | I18: =I14*Параметры!$C$6+I15*Параметры!$C$7+I16*Параметры!$C$8 -> 49064.022 | ... Y18: =Y14*Параметры!$C$6+Y15*Параметры!$C$7+Y16*Параметры!$C$8 -> 156055.87
A19: Разовые аудиты | B19: =B10*Параметры!$C$9 -> 2865.6 | C19: =C10*Параметры!$C$9 -> 2951.568 | D19: =D10*Параметры!$C$9 -> 3042.6941 | E19: =E10*Параметры!$C$9 -> 3139.2877 | F19: =F10*Параметры!$C$9 -> 3241.677 | G19: =G10*Параметры!$C$9 -> 3350.2096 | H19: =H10*Параметры!$C$9 -> 3465.2542 | I19: =I10*Параметры!$C$9 -> 3587.2014 | ... Y19: =Y10*Параметры!$C$9 -> 6905.7373
A20: Выручка всего | B20: =B18+B19 -> 9325.632 | C20: =C18+C19 -> 15742.431 | D20: =D18+D19 -> 22053.276 | E20: =E18+E19 -> 28276.358 | F20: =F18+F19 -> 34429.73 | G20: =G18+G19 -> 40531.366 | H20: =H18+H19 -> 46599.208 | I20: =I18+I19 -> 52651.224 | ... Y20: =Y18+Y19 -> 162961.6
A21: Переменные расходы
A22: API Яндекса: подписчики | B22: =(B14*Параметры!$C$11+B15*Параметры!$C$12+B16*Параметры!$C$13)*Параметры!$C$16 -> 856.14336 | C22: =(C14*Параметры!$C$11+C15*Параметры!$C$12+C16*Параметры!$C$13)*Параметры!$C$16 -> 1695.1639 | D22: =(D14*Параметры!$C$11+D15*Параметры!$C$12+D16*Параметры!$C$13)*Параметры!$C$16 -> 2519.4587 | E22: =(E14*Параметры!$C$11+E15*Параметры!$C$12+E16*Параметры!$C$13)*Параметры!$C$16 -> 3331.3976 | F22: =(F14*Параметры!$C$11+F15*Параметры!$C$12+F16*Параметры!$C$13)*Параметры!$C$16 -> 4133.3301 | G22: =(G14*Параметры!$C$11+G15*Параметры!$C$12+G16*Параметры!$C$13)*Параметры!$C$16 -> 4927.5917 | H22: =(H14*Параметры!$C$11+H15*Параметры!$C$12+H16*Параметры!$C$13)*Параметры!$C$16 -> 5716.5117 | I22: =(I14*Параметры!$C$11+I15*Параметры!$C$12+I16*Параметры!$C$13)*Параметры!$C$16 -> 6502.4193 | ... Y22: =(Y14*Параметры!$C$11+Y15*Параметры!$C$12+Y16*Параметры!$C$13)*Параметры!$C$16 -> 20681.971
A23: API Яндекса: разовые аудиты | B23: =B10*Параметры!$C$14 -> 39.9888 | C23: =C10*Параметры!$C$14 -> 41.188464 | D23: =D10*Параметры!$C$14 -> 42.460108 | E23: =E10*Параметры!$C$14 -> 43.80805 | F23: =F10*Параметры!$C$14 -> 45.236869 | G23: =G10*Параметры!$C$14 -> 46.751417 | H23: =H10*Параметры!$C$14 -> 48.356839 | I23: =I10*Параметры!$C$14 -> 50.058585 | ... Y23: =Y10*Параметры!$C$14 -> 96.368003
A24: API Яндекса: бесплатные проверки | B24: =B8*Параметры!$C$15 -> 19.2 | C24: =C8*Параметры!$C$15 -> 19.776 | D24: =D8*Параметры!$C$15 -> 20.38656 | E24: =E8*Параметры!$C$15 -> 21.033754 | F24: =F8*Параметры!$C$15 -> 21.719779 | G24: =G8*Параметры!$C$15 -> 22.446966 | H24: =H8*Параметры!$C$15 -> 23.217783 | I24: =I8*Параметры!$C$15 -> 24.03485 | ... Y24: =Y8*Параметры!$C$15 -> 46.269597
A25: LLM: тексты рекомендаций | B25: =(B14*Параметры!$C$20+B15*Параметры!$C$21+B16*Параметры!$C$22)*Параметры!$C$16*Параметры!$C$18+B10*Параметры!$C$18+B8*Параметры!$C$19 -> 342.09792 | C25: =(C14*Параметры!$C$20+C15*Параметры!$C$21+C16*Параметры!$C$22)*Параметры!$C$16*Параметры!$C$18+C10*Параметры!$C$18+C8*Параметры!$C$19 -> 432.20828 | D25: =(D14*Параметры!$C$20+D15*Параметры!$C$21+D16*Параметры!$C$22)*Параметры!$C$16*Параметры!$C$18+D10*Параметры!$C$18+D8*Параметры!$C$19 -> 521.33747 | E25: =(E14*Параметры!$C$20+E15*Параметры!$C$21+E16*Параметры!$C$22)*Параметры!$C$16*Параметры!$C$18+E10*Параметры!$C$18+E8*Параметры!$C$19 -> 609.74601 | F25: =(F14*Параметры!$C$20+F15*Параметры!$C$21+F16*Параметры!$C$22)*Параметры!$C$16*Параметры!$C$18+F10*Параметры!$C$18+F8*Параметры!$C$19 -> 697.69407 | G25: =(G14*Параметры!$C$20+G15*Параметры!$C$21+G16*Параметры!$C$22)*Параметры!$C$16*Параметры!$C$18+G10*Параметры!$C$18+G8*Параметры!$C$19 -> 785.44229 | H25: =(H14*Параметры!$C$20+H15*Параметры!$C$21+H16*Параметры!$C$22)*Параметры!$C$16*Параметры!$C$18+H10*Параметры!$C$18+H8*Параметры!$C$19 -> 873.25249 | I25: =(I14*Параметры!$C$20+I15*Параметры!$C$21+I16*Параметры!$C$22)*Параметры!$C$16*Параметры!$C$18+I10*Параметры!$C$18+I8*Параметры!$C$19 -> 961.38856 | ... Y25: =(Y14*Параметры!$C$20+Y15*Параметры!$C$21+Y16*Параметры!$C$22)*Параметры!$C$16*Параметры!$C$18+Y10*Параметры!$C$18+Y8*Параметры!$C$19 -> 2652.2687
A26: Эквайринг | B26: =B20*Параметры!$C$24 -> 354.37402 | C26: =C20*Параметры!$C$24 -> 598.21239 | D26: =D20*Параметры!$C$24 -> 838.0245 | E26: =E20*Параметры!$C$24 -> 1074.5016 | F26: =F20*Параметры!$C$24 -> 1308.3297 | G26: =G20*Параметры!$C$24 -> 1540.1919 | H26: =H20*Параметры!$C$24 -> 1770.7699 | I26: =I20*Параметры!$C$24 -> 2000.7465 | ... Y26: =Y20*Параметры!$C$24 -> 6192.541
A27: Налоги и взносы
A28: Выручка за 12 месяцев (для порога НДС) | B28: =SUM(B20) -> 9325.632 | C28: =SUM(B20:C20) -> 25068.063 | D28: =SUM(B20:D20) -> 47121.34 | E28: =SUM(B20:E20) -> 75397.697 | F28: =SUM(B20:F20) -> 109827.43 | G28: =SUM(B20:G20) -> 150358.79 | H28: =SUM(B20:H20) -> 196958 | I28: =SUM(B20:I20) -> 249609.23 | J28: =SUM(B20:J20) -> 308314.68 | K28: =SUM(B20:K20) -> 373094.77 | L28: =SUM(B20:L20) -> 443988.25 | M28: =SUM(B20:M20) -> 521052.5 | N28: =SUM(C20:N20) -> 595038.18 | O28: =SUM(D20:O20) -> 668949.67 | P28: =SUM(E20:P20) -> 743008.21 | Q28: =SUM(F20:Q20) -> 817436.99 | R28: =SUM(G20:R20) -> 892461.88 | S28: =SUM(H20:S20) -> 968312.15 | T28: =SUM(I20:T20) -> 1045221.1 | ... Y28: =SUM(N20:Y20) -> 1454192
A29: Налог УСН | B29: =B20*Параметры!$C$25 -> 559.53792 | C29: =C20*Параметры!$C$25 -> 944.54588 | D29: =D20*Параметры!$C$25 -> 1323.1966 | E29: =E20*Параметры!$C$25 -> 1696.5815 | F29: =F20*Параметры!$C$25 -> 2065.7838 | G29: =G20*Параметры!$C$25 -> 2431.882 | H29: =H20*Параметры!$C$25 -> 2795.9525 | I29: =I20*Параметры!$C$25 -> 3159.0734 | ... Y29: =Y20*Параметры!$C$25 -> 9777.6963
A30: НДС | B30: =IF(B28>Параметры!$C$26,B20*Параметры!$C$27,0) -> 0 | C30: =IF(C28>Параметры!$C$26,C20*Параметры!$C$27,0) -> 0 | D30: =IF(D28>Параметры!$C$26,D20*Параметры!$C$27,0) -> 0 | E30: =IF(E28>Параметры!$C$26,E20*Параметры!$C$27,0) -> 0 | F30: =IF(F28>Параметры!$C$26,F20*Параметры!$C$27,0) -> 0 | G30: =IF(G28>Параметры!$C$26,G20*Параметры!$C$27,0) -> 0 | H30: =IF(H28>Параметры!$C$26,H20*Параметры!$C$27,0) -> 0 | I30: =IF(I28>Параметры!$C$26,I20*Параметры!$C$27,0) -> 0 | ... Y30: =IF(Y28>Параметры!$C$26,Y20*Параметры!$C$27,0) -> 0
A31: Страховые взносы ИП | B31: =Параметры!$C$28/12+MAX(0,B20-Параметры!$C$29/12)*Параметры!$C$30 -> 4782.5 | C31: =Параметры!$C$28/12+MAX(0,C20-Параметры!$C$29/12)*Параметры!$C$30 -> 4782.5 | D31: =Параметры!$C$28/12+MAX(0,D20-Параметры!$C$29/12)*Параметры!$C$30 -> 4782.5 | E31: =Параметры!$C$28/12+MAX(0,E20-Параметры!$C$29/12)*Параметры!$C$30 -> 4815.2636 | F31: =Параметры!$C$28/12+MAX(0,F20-Параметры!$C$29/12)*Параметры!$C$30 -> 4876.7973 | G31: =Параметры!$C$28/12+MAX(0,G20-Параметры!$C$29/12)*Параметры!$C$30 -> 4937.8137 | H31: =Параметры!$C$28/12+MAX(0,H20-Параметры!$C$29/12)*Параметры!$C$30 -> 4998.4921 | I31: =Параметры!$C$28/12+MAX(0,I20-Параметры!$C$29/12)*Параметры!$C$30 -> 5059.0122 | ... Y31: =Параметры!$C$28/12+MAX(0,Y20-Параметры!$C$29/12)*Параметры!$C$30 -> 6162.116
A32: Постоянные расходы
A33: Сервер, база, касса, домен, прочее | B33: =Параметры!$C$32+Параметры!$C$33+Параметры!$C$34+Параметры!$C$35+Параметры!$C$36 -> 6799 | C33: =Параметры!$C$32+Параметры!$C$33+Параметры!$C$34+Параметры!$C$35+Параметры!$C$36 -> 6799 | D33: =Параметры!$C$32+Параметры!$C$33+Параметры!$C$34+Параметры!$C$35+Параметры!$C$36 -> 6799 | E33: =Параметры!$C$32+Параметры!$C$33+Параметры!$C$34+Параметры!$C$35+Параметры!$C$36 -> 6799 | F33: =Параметры!$C$32+Параметры!$C$33+Параметры!$C$34+Параметры!$C$35+Параметры!$C$36 -> 6799 | G33: =Параметры!$C$32+Параметры!$C$33+Параметры!$C$34+Параметры!$C$35+Параметры!$C$36 -> 6799 | H33: =Параметры!$C$32+Параметры!$C$33+Параметры!$C$34+Параметры!$C$35+Параметры!$C$36 -> 6799 | I33: =Параметры!$C$32+Параметры!$C$33+Параметры!$C$34+Параметры!$C$35+Параметры!$C$36 -> 6799 | ... Y33: =Параметры!$C$32+Параметры!$C$33+Параметры!$C$34+Параметры!$C$35+Параметры!$C$36 -> 6799
A34: Реклама | B34: =Параметры!$C$41 -> 30000 | C34: =Параметры!$C$41 -> 30000 | D34: =Параметры!$C$41 -> 30000 | E34: =Параметры!$C$41 -> 30000 | F34: =Параметры!$C$41 -> 30000 | G34: =Параметры!$C$41 -> 30000 | H34: =Параметры!$C$41 -> 30000 | I34: =Параметры!$C$41 -> 30000 | ... Y34: =Параметры!$C$41 -> 30000
A35: Работа владельцев | B35: =Параметры!$C$37 -> 0 | C35: =Параметры!$C$37 -> 0 | D35: =Параметры!$C$37 -> 0 | E35: =Параметры!$C$37 -> 0 | F35: =Параметры!$C$37 -> 0 | G35: =Параметры!$C$37 -> 0 | H35: =Параметры!$C$37 -> 0 | I35: =Параметры!$C$37 -> 0 | ... Y35: =Параметры!$C$37 -> 0
A36: Итог
A37: Расходы всего | B37: =B22+B23+B24+B25+B26+B29+B30+B31+B33+B34+B35 -> 43752.842 | C37: =C22+C23+C24+C25+C26+C29+C30+C31+C33+C34+C35 -> 45312.595 | D37: =D22+D23+D24+D25+D26+D29+D30+D31+D33+D34+D35 -> 46846.364 | E37: =E22+E23+E24+E25+E26+E29+E30+E31+E33+E34+E35 -> 48391.332 | F37: =F22+F23+F24+F25+F26+F29+F30+F31+F33+F34+F35 -> 49947.892 | G37: =G22+G23+G24+G25+G26+G29+G30+G31+G33+G34+G35 -> 51491.12 | H37: =H22+H23+H24+H25+H26+H29+H30+H31+H33+H34+H35 -> 53025.553 | I37: =I22+I23+I24+I25+I26+I29+I30+I31+I33+I34+I35 -> 54555.733 | ... Y37: =Y22+Y23+Y24+Y25+Y26+Y29+Y30+Y31+Y33+Y34+Y35 -> 82408.231
A38: Прибыль за месяц | B38: =B20-B37 -> -34427.21 | C38: =C20-C37 -> -29570.164 | D38: =D20-D37 -> -24793.088 | E38: =E20-E37 -> -20114.975 | F38: =F20-F37 -> -15518.162 | G38: =G20-G37 -> -10959.754 | H38: =H20-H37 -> -6426.345 | I38: =I20-I37 -> -1904.5099 | ... Y38: =Y20-Y37 -> 80553.374
A39: Накопленный итог | B39: =B38 -> -34427.21 | C39: =B39+C38 -> -63997.374 | D39: =C39+D38 -> -88790.461 | E39: =D39+E38 -> -108905.44 | F39: =E39+F38 -> -124423.6 | G39: =F39+G38 -> -135383.35 | H39: =G39+H38 -> -141809.7 | I39: =H39+I38 -> -143714.21 | J39: =I39+J38 -> -141094.97 | ... Y39: =X39+Y38 -> 485940.32
A40: Месяц прибыльный (1 — да) | B40: =IF(B38>=0,1,0) -> 0 | C40: =IF(C38>=0,1,0) -> 0 | D40: =IF(D38>=0,1,0) -> 0 | E40: =IF(E38>=0,1,0) -> 0 | F40: =IF(F38>=0,1,0) -> 0 | G40: =IF(G38>=0,1,0) -> 0 | H40: =IF(H38>=0,1,0) -> 0 | I40: =IF(I38>=0,1,0) -> 0 | ... Y40: =IF(Y38>=0,1,0) -> 1
A41: Вложения возвращены (1 — да) | B41: =IF(B39>=0,1,0) -> 0 | C41: =IF(C39>=0,1,0) -> 0 | D41: =IF(D39>=0,1,0) -> 0 | E41: =IF(E39>=0,1,0) -> 0 | F41: =IF(F39>=0,1,0) -> 0 | G41: =IF(G39>=0,1,0) -> 0 | H41: =IF(H39>=0,1,0) -> 0 | I41: =IF(I39>=0,1,0) -> 0 | ... Y41: =IF(Y39>=0,1,0) -> 1

Sheet Смелый
A1: yaSEO — сценарий «смелый», 24 месяцев, ₽
A3: Месяц | B3: 1 | C3: 2 | D3: 3 | E3: 4 | F3: 5 | G3: 6 | H3: 7 | I3: 8 | J3: 9 | K3: 10 | L3: 11 | M3: 12 | N3: 13 | O3: 14 | P3: 15 | Q3: 16 | R3: 17 | S3: 18 | T3: 19 | U3: 20 | V3: 21 | W3: 22 | X3: 23 | Y3: 24
A4: Поток
A5: Посетители бесплатных каналов | B5: =Параметры!$D$39 -> 1200 | C5: =B5*(1+Параметры!$D$40) -> 1320 | D5: =C5*(1+Параметры!$D$40) -> 1452 | E5: =D5*(1+Параметры!$D$40) -> 1597.2 | F5: =E5*(1+Параметры!$D$40) -> 1756.92 | G5: =F5*(1+Параметры!$D$40) -> 1932.612 | H5: =G5*(1+Параметры!$D$40) -> 2125.8732 | I5: =H5*(1+Параметры!$D$40) -> 2338.4605 | J5: =I5*(1+Параметры!$D$40) -> 2572.3066 | ... Y5: =X5*(1+Параметры!$D$40) -> 10745.163
A6: Посетители из рекламы | B6: =IF(Параметры!$D$42>0,Параметры!$D$41/Параметры!$D$42,0) -> 2500 | C6: =IF(Параметры!$D$42>0,Параметры!$D$41/Параметры!$D$42,0) -> 2500 | D6: =IF(Параметры!$D$42>0,Параметры!$D$41/Параметры!$D$42,0) -> 2500 | E6: =IF(Параметры!$D$42>0,Параметры!$D$41/Параметры!$D$42,0) -> 2500 | F6: =IF(Параметры!$D$42>0,Параметры!$D$41/Параметры!$D$42,0) -> 2500 | G6: =IF(Параметры!$D$42>0,Параметры!$D$41/Параметры!$D$42,0) -> 2500 | H6: =IF(Параметры!$D$42>0,Параметры!$D$41/Параметры!$D$42,0) -> 2500 | I6: =IF(Параметры!$D$42>0,Параметры!$D$41/Параметры!$D$42,0) -> 2500 | ... Y6: =IF(Параметры!$D$42>0,Параметры!$D$41/Параметры!$D$42,0) -> 2500
A7: Посетители всего | B7: =B5+B6 -> 3700 | C7: =C5+C6 -> 3820 | D7: =D5+D6 -> 3952 | E7: =E5+E6 -> 4097.2 | F7: =F5+F6 -> 4256.92 | G7: =G5+G6 -> 4432.612 | H7: =H5+H6 -> 4625.8732 | I7: =I5+I6 -> 4838.4605 | ... Y7: =Y5+Y6 -> 13245.163
A8: Бесплатные проверки (регистрации) | B8: =B7*Параметры!$D$44 -> 296 | C8: =C7*Параметры!$D$44 -> 305.6 | D8: =D7*Параметры!$D$44 -> 316.16 | E8: =E7*Параметры!$D$44 -> 327.776 | F8: =F7*Параметры!$D$44 -> 340.5536 | G8: =G7*Параметры!$D$44 -> 354.60896 | H8: =H7*Параметры!$D$44 -> 370.06986 | I8: =I7*Параметры!$D$44 -> 387.07684 | ... Y8: =Y7*Параметры!$D$44 -> 1059.613
A9: Новые подписчики | B9: =B8*Параметры!$D$45 -> 20.72 | C9: =C8*Параметры!$D$45 -> 21.392 | D9: =D8*Параметры!$D$45 -> 22.1312 | E9: =E8*Параметры!$D$45 -> 22.94432 | F9: =F8*Параметры!$D$45 -> 23.838752 | G9: =G8*Параметры!$D$45 -> 24.822627 | H9: =H8*Параметры!$D$45 -> 25.90489 | I9: =I8*Параметры!$D$45 -> 27.095379 | ... Y9: =Y8*Параметры!$D$45 -> 74.172912
A10: Разовые аудиты | B10: =B8*Параметры!$D$46 -> 14.8 | C10: =C8*Параметры!$D$46 -> 15.28 | D10: =D8*Параметры!$D$46 -> 15.808 | E10: =E8*Параметры!$D$46 -> 16.3888 | F10: =F8*Параметры!$D$46 -> 17.02768 | G10: =G8*Параметры!$D$46 -> 17.730448 | H10: =H8*Параметры!$D$46 -> 18.503493 | I10: =I8*Параметры!$D$46 -> 19.353842 | ... Y10: =Y8*Параметры!$D$46 -> 52.980652
A11: Подписчики
A12: Ушло подписчиков | B12: =0 -> 0 | C12: =B13*Параметры!$D$47 -> 0.6216 | D12: =C13*Параметры!$D$47 -> 1.244712 | E12: =D13*Параметры!$D$47 -> 1.8713066 | F12: =E13*Параметры!$D$47 -> 2.503497 | G12: =F13*Параметры!$D$47 -> 3.1435547 | H12: =G13*Параметры!$D$47 -> 3.7939269 | I12: =H13*Параметры!$D$47 -> 4.4572558 | J12: =I13*Параметры!$D$47 -> 5.1363995 | ... Y12: =X13*Параметры!$D$47 -> 20.16811
A13: Активные подписчики | B13: =B9 -> 20.72 | C13: =B13+C9-C12 -> 41.4904 | D13: =C13+D9-D12 -> 62.376888 | E13: =D13+E9-E12 -> 83.449901 | F13: =E13+F9-F12 -> 104.78516 | G13: =F13+G9-G12 -> 126.46423 | H13: =G13+H9-H12 -> 148.57519 | I13: =H13+I9-I12 -> 171.21332 | J13: =I13+J9-J12 -> 194.48183 | ... Y13: =X13+Y9-Y12 -> 726.27514
A14: из них Старт | B14: =B13*Параметры!$D$49 -> 12.432 | C14: =C13*Параметры!$D$49 -> 24.89424 | D14: =D13*Параметры!$D$49 -> 37.426133 | E14: =E13*Параметры!$D$49 -> 50.069941 | F14: =F13*Параметры!$D$49 -> 62.871094 | G14: =G13*Параметры!$D$49 -> 75.878537 | H14: =H13*Параметры!$D$49 -> 89.145115 | I14: =I13*Параметры!$D$49 -> 102.72799 | ... Y14: =Y13*Параметры!$D$49 -> 435.76508
A15: из них Про | B15: =B13*Параметры!$D$50 -> 6.216 | C15: =C13*Параметры!$D$50 -> 12.44712 | D15: =D13*Параметры!$D$50 -> 18.713066 | E15: =E13*Параметры!$D$50 -> 25.03497 | F15: =F13*Параметры!$D$50 -> 31.435547 | G15: =G13*Параметры!$D$50 -> 37.939269 | H15: =H13*Параметры!$D$50 -> 44.572558 | I15: =I13*Параметры!$D$50 -> 51.363995 | ... Y15: =Y13*Параметры!$D$50 -> 217.88254
A16: из них Агентство | B16: =B13*Параметры!$D$51 -> 2.072 | C16: =C13*Параметры!$D$51 -> 4.14904 | D16: =D13*Параметры!$D$51 -> 6.2376888 | E16: =E13*Параметры!$D$51 -> 8.3449901 | F16: =F13*Параметры!$D$51 -> 10.478516 | G16: =G13*Параметры!$D$51 -> 12.646423 | H16: =H13*Параметры!$D$51 -> 14.857519 | I16: =I13*Параметры!$D$51 -> 17.121332 | ... Y16: =Y13*Параметры!$D$51 -> 72.627514
A17: Выручка
A18: Подписки | B18: =B14*Параметры!$D$6+B15*Параметры!$D$7+B16*Параметры!$D$8 -> 82486.32 | C18: =C14*Параметры!$D$6+C15*Параметры!$D$7+C16*Параметры!$D$8 -> 165173.28 | D18: =D14*Параметры!$D$6+D15*Параметры!$D$7+D16*Параметры!$D$8 -> 248322.39 | E18: =E14*Параметры!$D$6+E15*Параметры!$D$7+E16*Параметры!$D$8 -> 332214.06 | F18: =F14*Параметры!$D$6+F15*Параметры!$D$7+F16*Параметры!$D$8 -> 417149.71 | G18: =G14*Параметры!$D$6+G15*Параметры!$D$7+G16*Параметры!$D$8 -> 503454.09 | H18: =H14*Параметры!$D$6+H15*Параметры!$D$7+H16*Параметры!$D$8 -> 591477.84 | I18: =I14*Параметры!$D$6+I15*Параметры!$D$7+I16*Параметры!$D$8 -> 681600.21 | ... Y18: =Y14*Параметры!$D$6+Y15*Параметры!$D$7+Y16*Параметры!$D$8 -> 2891301.3
A19: Разовые аудиты | B19: =B10*Параметры!$D$9 -> 29452 | C19: =C10*Параметры!$D$9 -> 30407.2 | D19: =D10*Параметры!$D$9 -> 31457.92 | E19: =E10*Параметры!$D$9 -> 32613.712 | F19: =F10*Параметры!$D$9 -> 33885.083 | G19: =G10*Параметры!$D$9 -> 35283.592 | H19: =H10*Параметры!$D$9 -> 36821.951 | I19: =I10*Параметры!$D$9 -> 38514.146 | ... Y19: =Y10*Параметры!$D$9 -> 105431.5
A20: Выручка всего | B20: =B18+B19 -> 111938.32 | C20: =C18+C19 -> 195580.48 | D20: =D18+D19 -> 279780.31 | E20: =E18+E19 -> 364827.77 | F20: =F18+F19 -> 451034.79 | G20: =G18+G19 -> 538737.69 | H20: =H18+H19 -> 628299.79 | I20: =I18+I19 -> 720114.35 | ... Y20: =Y18+Y19 -> 2996732.8
A21: Переменные расходы
A22: API Яндекса: подписчики | B22: =(B14*Параметры!$D$11+B15*Параметры!$D$12+B16*Параметры!$D$13)*Параметры!$D$16 -> 9668.988 | C22: =(C14*Параметры!$D$11+C15*Параметры!$D$12+C16*Параметры!$D$13)*Параметры!$D$16 -> 19361.495 | D22: =(D14*Параметры!$D$11+D15*Параметры!$D$12+D16*Параметры!$D$13)*Параметры!$D$16 -> 29108.175 | E22: =(E14*Параметры!$D$11+E15*Параметры!$D$12+E16*Параметры!$D$13)*Параметры!$D$16 -> 38941.896 | F22: =(F14*Параметры!$D$11+F15*Параметры!$D$12+F16*Параметры!$D$13)*Параметры!$D$16 -> 48897.993 | G22: =(G14*Параметры!$D$11+G15*Параметры!$D$12+G16*Параметры!$D$13)*Параметры!$D$16 -> 59014.532 | H22: =(H14*Параметры!$D$11+H15*Параметры!$D$12+H16*Параметры!$D$13)*Параметры!$D$16 -> 69332.613 | I22: =(I14*Параметры!$D$11+I15*Параметры!$D$12+I16*Параметры!$D$13)*Параметры!$D$16 -> 79896.693 | ... Y22: =(Y14*Параметры!$D$11+Y15*Параметры!$D$12+Y16*Параметры!$D$13)*Параметры!$D$16 -> 338916.29
A23: API Яндекса: разовые аудиты | B23: =B10*Параметры!$D$14 -> 410.996 | C23: =C10*Параметры!$D$14 -> 424.3256 | D23: =D10*Параметры!$D$14 -> 438.98816 | E23: =E10*Параметры!$D$14 -> 455.11698 | F23: =F10*Параметры!$D$14 -> 472.85867 | G23: =G10*Параметры!$D$14 -> 492.37454 | H23: =H10*Параметры!$D$14 -> 513.842 | I23: =I10*Параметры!$D$14 -> 537.45619 | ... Y23: =Y10*Параметры!$D$14 -> 1471.2727
A24: API Яндекса: бесплатные проверки | B24: =B8*Параметры!$D$15 -> 118.4 | C24: =C8*Параметры!$D$15 -> 122.24 | D24: =D8*Параметры!$D$15 -> 126.464 | E24: =E8*Параметры!$D$15 -> 131.1104 | F24: =F8*Параметры!$D$15 -> 136.22144 | G24: =G8*Параметры!$D$15 -> 141.84358 | H24: =H8*Параметры!$D$15 -> 148.02794 | I24: =I8*Параметры!$D$15 -> 154.83074 | ... Y24: =Y8*Параметры!$D$15 -> 423.84521
A25: LLM: тексты рекомендаций | B25: =(B14*Параметры!$D$20+B15*Параметры!$D$21+B16*Параметры!$D$22)*Параметры!$D$16*Параметры!$D$18+B10*Параметры!$D$18+B8*Параметры!$D$19 -> 2639.8464 | C25: =(C14*Параметры!$D$20+C15*Параметры!$D$21+C16*Параметры!$D$22)*Параметры!$D$16*Параметры!$D$18+C10*Параметры!$D$18+C8*Параметры!$D$19 -> 3632.3028 | D25: =(D14*Параметры!$D$20+D15*Параметры!$D$21+D16*Параметры!$D$22)*Параметры!$D$16*Параметры!$D$18+D10*Параметры!$D$18+D8*Параметры!$D$19 -> 4635.5268 | E25: =(E14*Параметры!$D$20+E15*Параметры!$D$21+E16*Параметры!$D$22)*Параметры!$D$16*Параметры!$D$18+E10*Параметры!$D$18+E8*Параметры!$D$19 -> 5653.2493 | F25: =(F14*Параметры!$D$20+F15*Параметры!$D$21+F16*Параметры!$D$22)*Параметры!$D$16*Параметры!$D$18+F10*Параметры!$D$18+F8*Параметры!$D$19 -> 6689.495 | G25: =(G14*Параметры!$D$20+G15*Параметры!$D$21+G16*Параметры!$D$22)*Параметры!$D$16*Параметры!$D$18+G10*Параметры!$D$18+G8*Параметры!$D$19 -> 7748.6136 | H25: =(H14*Параметры!$D$20+H15*Параметры!$D$21+H16*Параметры!$D$22)*Параметры!$D$16*Параметры!$D$18+H10*Параметры!$D$18+H8*Параметры!$D$19 -> 8835.315 | I25: =(I14*Параметры!$D$20+I15*Параметры!$D$21+I16*Параметры!$D$22)*Параметры!$D$16*Параметры!$D$18+I10*Параметры!$D$18+I8*Параметры!$D$19 -> 9954.7074 | ... Y25: =(Y14*Параметры!$D$20+Y15*Параметры!$D$21+Y16*Параметры!$D$22)*Параметры!$D$16*Параметры!$D$18+Y10*Параметры!$D$18+Y8*Параметры!$D$19 -> 38872.905
A26: Эквайринг | B26: =B20*Параметры!$D$24 -> 4253.6562 | C26: =C20*Параметры!$D$24 -> 7432.0583 | D26: =D20*Параметры!$D$24 -> 10631.652 | E26: =E20*Параметры!$D$24 -> 13863.455 | F26: =F20*Параметры!$D$24 -> 17139.322 | G26: =G20*Параметры!$D$24 -> 20472.032 | H26: =H20*Параметры!$D$24 -> 23875.392 | I26: =I20*Параметры!$D$24 -> 27364.345 | ... Y26: =Y20*Параметры!$D$24 -> 113875.85
A27: Налоги и взносы
A28: Выручка за 12 месяцев (для порога НДС) | B28: =SUM(B20) -> 111938.32 | C28: =SUM(B20:C20) -> 307518.8 | D28: =SUM(B20:D20) -> 587299.11 | E28: =SUM(B20:E20) -> 952126.88 | F28: =SUM(B20:F20) -> 1403161.7 | G28: =SUM(B20:G20) -> 1941899.4 | H28: =SUM(B20:H20) -> 2570199.1 | I28: =SUM(B20:I20) -> 3290313.5 | J28: =SUM(B20:J20) -> 4104921.2 | K28: =SUM(B20:K20) -> 5017164.1 | L28: =SUM(B20:L20) -> 6030687.4 | M28: =SUM(B20:M20) -> 7149684.2 | N28: =SUM(C20:N20) -> 8267007 | O28: =SUM(D20:O20) -> 9416394.2 | P28: =SUM(E20:P20) -> 10603442 | Q28: =SUM(F20:Q20) -> 11834236 | R28: =SUM(G20:R20) -> 13115398 | S28: =SUM(H20:S20) -> 14454147 | T28: =SUM(I20:T20) -> 15858357 | ... Y28: =SUM(N20:Y20) -> 24191992
A29: Налог УСН | B29: =B20*Параметры!$D$25 -> 6716.2992 | C29: =C20*Параметры!$D$25 -> 11734.829 | D29: =D20*Параметры!$D$25 -> 16786.819 | E29: =E20*Параметры!$D$25 -> 21889.666 | F29: =F20*Параметры!$D$25 -> 27062.087 | G29: =G20*Параметры!$D$25 -> 32324.261 | H29: =H20*Параметры!$D$25 -> 37697.987 | I29: =I20*Параметры!$D$25 -> 43206.861 | ... Y29: =Y20*Параметры!$D$25 -> 179803.97
A30: НДС | B30: =IF(B28>Параметры!$D$26,B20*Параметры!$D$27,0) -> 0 | C30: =IF(C28>Параметры!$D$26,C20*Параметры!$D$27,0) -> 0 | D30: =IF(D28>Параметры!$D$26,D20*Параметры!$D$27,0) -> 0 | E30: =IF(E28>Параметры!$D$26,E20*Параметры!$D$27,0) -> 0 | F30: =IF(F28>Параметры!$D$26,F20*Параметры!$D$27,0) -> 0 | G30: =IF(G28>Параметры!$D$26,G20*Параметры!$D$27,0) -> 0 | H30: =IF(H28>Параметры!$D$26,H20*Параметры!$D$27,0) -> 0 | I30: =IF(I28>Параметры!$D$26,I20*Параметры!$D$27,0) -> 0 | ... Y30: =IF(Y28>Параметры!$D$26,Y20*Параметры!$D$27,0) -> 149836.64
A31: Страховые взносы ИП | B31: =Параметры!$D$28/12+MAX(0,B20-Параметры!$D$29/12)*Параметры!$D$30 -> 5651.8832 | C31: =Параметры!$D$28/12+MAX(0,C20-Параметры!$D$29/12)*Параметры!$D$30 -> 6488.3048 | D31: =Параметры!$D$28/12+MAX(0,D20-Параметры!$D$29/12)*Параметры!$D$30 -> 7330.3031 | E31: =Параметры!$D$28/12+MAX(0,E20-Параметры!$D$29/12)*Параметры!$D$30 -> 8180.7777 | F31: =Параметры!$D$28/12+MAX(0,F20-Параметры!$D$29/12)*Параметры!$D$30 -> 9042.8479 | G31: =Параметры!$D$28/12+MAX(0,G20-Параметры!$D$29/12)*Параметры!$D$30 -> 9919.8769 | H31: =Параметры!$D$28/12+MAX(0,H20-Параметры!$D$29/12)*Параметры!$D$30 -> 10815.498 | I31: =Параметры!$D$28/12+MAX(0,I20-Параметры!$D$29/12)*Параметры!$D$30 -> 11733.644 | ... Y31: =Параметры!$D$28/12+MAX(0,Y20-Параметры!$D$29/12)*Параметры!$D$30 -> 34499.828
A32: Постоянные расходы
A33: Сервер, база, касса, домен, прочее | B33: =Параметры!$D$32+Параметры!$D$33+Параметры!$D$34+Параметры!$D$35+Параметры!$D$36 -> 6799 | C33: =Параметры!$D$32+Параметры!$D$33+Параметры!$D$34+Параметры!$D$35+Параметры!$D$36 -> 6799 | D33: =Параметры!$D$32+Параметры!$D$33+Параметры!$D$34+Параметры!$D$35+Параметры!$D$36 -> 6799 | E33: =Параметры!$D$32+Параметры!$D$33+Параметры!$D$34+Параметры!$D$35+Параметры!$D$36 -> 6799 | F33: =Параметры!$D$32+Параметры!$D$33+Параметры!$D$34+Параметры!$D$35+Параметры!$D$36 -> 6799 | G33: =Параметры!$D$32+Параметры!$D$33+Параметры!$D$34+Параметры!$D$35+Параметры!$D$36 -> 6799 | H33: =Параметры!$D$32+Параметры!$D$33+Параметры!$D$34+Параметры!$D$35+Параметры!$D$36 -> 6799 | I33: =Параметры!$D$32+Параметры!$D$33+Параметры!$D$34+Параметры!$D$35+Параметры!$D$36 -> 6799 | ... Y33: =Параметры!$D$32+Параметры!$D$33+Параметры!$D$34+Параметры!$D$35+Параметры!$D$36 -> 6799
A34: Реклама | B34: =Параметры!$D$41 -> 100000 | C34: =Параметры!$D$41 -> 100000 | D34: =Параметры!$D$41 -> 100000 | E34: =Параметры!$D$41 -> 100000 | F34: =Параметры!$D$41 -> 100000 | G34: =Параметры!$D$41 -> 100000 | H34: =Параметры!$D$41 -> 100000 | I34: =Параметры!$D$41 -> 100000 | ... Y34: =Параметры!$D$41 -> 100000
A35: Работа владельцев | B35: =Параметры!$D$37 -> 0 | C35: =Параметры!$D$37 -> 0 | D35: =Параметры!$D$37 -> 0 | E35: =Параметры!$D$37 -> 0 | F35: =Параметры!$D$37 -> 0 | G35: =Параметры!$D$37 -> 0 | H35: =Параметры!$D$37 -> 0 | I35: =Параметры!$D$37 -> 0 | ... Y35: =Параметры!$D$37 -> 0
A36: Итог
A37: Расходы всего | B37: =B22+B23+B24+B25+B26+B29+B30+B31+B33+B34+B35 -> 136259.07 | C37: =C22+C23+C24+C25+C26+C29+C30+C31+C33+C34+C35 -> 155994.56 | D37: =D22+D23+D24+D25+D26+D29+D30+D31+D33+D34+D35 -> 175856.93 | E37: =E22+E23+E24+E25+E26+E29+E30+E31+E33+E34+E35 -> 195914.27 | F37: =F22+F23+F24+F25+F26+F29+F30+F31+F33+F34+F35 -> 216239.83 | G37: =G22+G23+G24+G25+G26+G29+G30+G31+G33+G34+G35 -> 236912.53 | H37: =H22+H23+H24+H25+H26+H29+H30+H31+H33+H34+H35 -> 258017.68 | I37: =I22+I23+I24+I25+I26+I29+I30+I31+I33+I34+I35 -> 279647.54 | ... Y37: =Y22+Y23+Y24+Y25+Y26+Y29+Y30+Y31+Y33+Y34+Y35 -> 964499.61
A38: Прибыль за месяц | B38: =B20-B37 -> -24320.749 | C38: =C20-C37 -> 39585.927 | D38: =D20-D37 -> 103923.38 | E38: =E20-E37 -> 168913.5 | F38: =F20-F37 -> 234794.96 | G38: =G20-G37 -> 301825.15 | H38: =H20-H37 -> 370282.11 | I38: =I20-I37 -> 440466.82 | ... Y38: =Y20-Y37 -> 2032233.2
A39: Накопленный итог | B39: =B38 -> -24320.749 | C39: =B39+C38 -> 15265.178 | D39: =C39+D38 -> 119188.56 | E39: =D39+E38 -> 288102.06 | F39: =E39+F38 -> 522897.02 | G39: =F39+G38 -> 824722.18 | H39: =G39+H38 -> 1195004.3 | I39: =H39+I38 -> 1635471.1 | J39: =I39+J38 -> 2148176.7 | ... Y39: =X39+Y38 -> 20908532
A40: Месяц прибыльный (1 — да) | B40: =IF(B38>=0,1,0) -> 0 | C40: =IF(C38>=0,1,0) -> 1 | D40: =IF(D38>=0,1,0) -> 1 | E40: =IF(E38>=0,1,0) -> 1 | F40: =IF(F38>=0,1,0) -> 1 | G40: =IF(G38>=0,1,0) -> 1 | H40: =IF(H38>=0,1,0) -> 1 | I40: =IF(I38>=0,1,0) -> 1 | ... Y40: =IF(Y38>=0,1,0) -> 1
A41: Вложения возвращены (1 — да) | B41: =IF(B39>=0,1,0) -> 0 | C41: =IF(C39>=0,1,0) -> 1 | D41: =IF(D39>=0,1,0) -> 1 | E41: =IF(E39>=0,1,0) -> 1 | F41: =IF(F39>=0,1,0) -> 1 | G41: =IF(G39>=0,1,0) -> 1 | H41: =IF(H39>=0,1,0) -> 1 | I41: =IF(I39>=0,1,0) -> 1 | ... Y41: =IF(Y39>=0,1,0) -> 1
